<?xml version="1.0" encoding="UTF-8"?>
<testng-results ignored="0" total="4" passed="1" failed="2" skipped="1">
  <reporter-output>
  </reporter-output>
  <suite started-at="2025-03-07T17:09:01 EET" name="Default Suite" finished-at="2025-03-07T17:09:03 EET" duration-ms="1126">
    <groups>
    </groups>
    <test started-at="2025-03-07T17:09:01 EET" name="TestNG" finished-at="2025-03-07T17:09:03 EET" duration-ms="1126">
      <class name="DemoTestNG.DummyTests">
        <test-method signature="test1()[pri:0, instance:DemoTestNG.DummyTests@2c4d1ac]" started-at="2025-03-07T17:09:01 EET" name="test1" finished-at="2025-03-07T17:09:01 EET" duration-ms="9" status="PASS">
          <reporter-output>
          </reporter-output>
        </test-method> <!-- test1 -->
        <test-method signature="test2()[pri:0, instance:DemoTestNG.DummyTests@2c4d1ac]" started-at="2025-03-07T17:09:01 EET" name="test2" finished-at="2025-03-07T17:09:01 EET" duration-ms="11" status="FAIL">
          <exception class="java.lang.AssertionError">
            <message>
              <![CDATA[expected [true] but found [false]]]>
            </message>
            <full-stacktrace>
              <![CDATA[java.lang.AssertionError: expected [true] but found [false]
at org.testng.Assert.fail(Assert.java:111)
at org.testng.Assert.failNotEquals(Assert.java:1578)
at org.testng.Assert.assertTrue(Assert.java:57)
at org.testng.Assert.assertTrue(Assert.java:67)
at DemoTestNG.DummyTests.test2(DummyTests.java:20)
at java.base/jdk.internal.reflect.DirectMethodHandleAccessor.invoke(DirectMethodHandleAccessor.java:103)
at java.base/java.lang.reflect.Method.invoke(Method.java:580)
at org.testng.internal.invokers.MethodInvocationHelper.invokeMethod(MethodInvocationHelper.java:141)
at org.testng.internal.invokers.TestInvoker.invokeMethod(TestInvoker.java:686)
at org.testng.internal.invokers.TestInvoker.invokeTestMethod(TestInvoker.java:230)
at org.testng.internal.invokers.MethodRunner.runInSequence(MethodRunner.java:63)
at org.testng.internal.invokers.TestInvoker$MethodInvocationAgent.invoke(TestInvoker.java:992)
at org.testng.internal.invokers.TestInvoker.invokeTestMethods(TestInvoker.java:203)
at org.testng.internal.invokers.TestMethodWorker.invokeTestMethods(TestMethodWorker.java:154)
at org.testng.internal.invokers.TestMethodWorker.run(TestMethodWorker.java:134)
at java.base/java.util.ArrayList.forEach(ArrayList.java:1596)
at org.testng.TestRunner.privateRun(TestRunner.java:739)
at org.testng.TestRunner.run(TestRunner.java:614)
at org.testng.SuiteRunner.runTest(SuiteRunner.java:421)
at org.testng.SuiteRunner.runSequentially(SuiteRunner.java:413)
at org.testng.SuiteRunner.privateRun(SuiteRunner.java:373)
at org.testng.SuiteRunner.run(SuiteRunner.java:312)
at org.testng.SuiteRunnerWorker.runSuite(SuiteRunnerWorker.java:52)
at org.testng.SuiteRunnerWorker.run(SuiteRunnerWorker.java:95)
at org.testng.TestNG.runSuitesSequentially(TestNG.java:1274)
at org.testng.TestNG.runSuitesLocally(TestNG.java:1208)
at org.testng.TestNG.runSuites(TestNG.java:1112)
at org.testng.TestNG.run(TestNG.java:1079)
at com.intellij.rt.testng.IDEARemoteTestNG.run(IDEARemoteTestNG.java:66)
at com.intellij.rt.testng.RemoteTestNGStarter.main(RemoteTestNGStarter.java:109)
]]>
            </full-stacktrace>
          </exception> <!-- java.lang.AssertionError -->
          <reporter-output>
          </reporter-output>
        </test-method> <!-- test2 -->
        <test-method signature="test3()[pri:0, instance:DemoTestNG.DummyTests@2c4d1ac]" started-at="2025-03-07T17:09:01 EET" name="test3" finished-at="2025-03-07T17:09:02 EET" duration-ms="1022" status="FAIL">
          <exception class="org.testng.internal.thread.ThreadTimeoutException">
            <message>
              <![CDATA[Method DemoTestNG.DummyTests.test3() didn't finish within the time-out 1000]]>
            </message>
            <full-stacktrace>
              <![CDATA[org.testng.internal.thread.ThreadTimeoutException: Method DemoTestNG.DummyTests.test3() didn't finish within the time-out 1000
at java.base/java.lang.Thread.sleep0(Native Method)
at java.base/java.lang.Thread.sleep(Thread.java:509)
at DemoTestNG.DummyTests.test3(DummyTests.java:26)
at java.base/jdk.internal.reflect.DirectMethodHandleAccessor.invoke(DirectMethodHandleAccessor.java:103)
at java.base/java.lang.reflect.Method.invoke(Method.java:580)
at org.testng.internal.invokers.MethodInvocationHelper.invokeMethod(MethodInvocationHelper.java:141)
at org.testng.internal.invokers.InvokeMethodRunnable.runOne(InvokeMethodRunnable.java:47)
at org.testng.internal.invokers.InvokeMethodRunnable.call(InvokeMethodRunnable.java:76)
at org.testng.internal.invokers.InvokeMethodRunnable.call(InvokeMethodRunnable.java:11)
at java.base/java.util.concurrent.FutureTask.run(FutureTask.java:317)
at java.base/java.util.concurrent.ThreadPoolExecutor.runWorker(ThreadPoolExecutor.java:1144)
at java.base/java.util.concurrent.ThreadPoolExecutor$Worker.run(ThreadPoolExecutor.java:642)
at java.base/java.lang.Thread.run(Thread.java:1583)
]]>
            </full-stacktrace>
          </exception> <!-- org.testng.internal.thread.ThreadTimeoutException -->
          <reporter-output>
          </reporter-output>
        </test-method> <!-- test3 -->
        <test-method signature="test4()[pri:0, instance:DemoTestNG.DummyTests@2c4d1ac]" started-at="2025-03-07T17:09:03 EET" name="test4" finished-at="2025-03-07T17:09:03 EET" depends-on-methods="DemoTestNG.DummyTests.test3" duration-ms="1" status="SKIP">
          <exception class="java.lang.Throwable">
            <message>
              <![CDATA[Method DemoTestNG.DummyTests.test4() on instance DemoTestNG.DummyTests@2c4d1ac depends on not successfully finished methods 
[DemoTestNG.DummyTests.test3() on instance DemoTestNG.DummyTests@2c4d1ac]]]>
            </message>
            <full-stacktrace>
              <![CDATA[java.lang.Throwable: Method DemoTestNG.DummyTests.test4() on instance DemoTestNG.DummyTests@2c4d1ac depends on not successfully finished methods 
[DemoTestNG.DummyTests.test3() on instance DemoTestNG.DummyTests@2c4d1ac]
at org.testng.internal.invokers.TestInvoker.invokeTestMethods(TestInvoker.java:159)
at org.testng.internal.invokers.TestMethodWorker.invokeTestMethods(TestMethodWorker.java:154)
at org.testng.internal.invokers.TestMethodWorker.run(TestMethodWorker.java:134)
at java.base/java.util.ArrayList.forEach(ArrayList.java:1596)
at org.testng.TestRunner.privateRun(TestRunner.java:739)
at org.testng.TestRunner.run(TestRunner.java:614)
at org.testng.SuiteRunner.runTest(SuiteRunner.java:421)
at org.testng.SuiteRunner.runSequentially(SuiteRunner.java:413)
at org.testng.SuiteRunner.privateRun(SuiteRunner.java:373)
at org.testng.SuiteRunner.run(SuiteRunner.java:312)
at org.testng.SuiteRunnerWorker.runSuite(SuiteRunnerWorker.java:52)
at org.testng.SuiteRunnerWorker.run(SuiteRunnerWorker.java:95)
at org.testng.TestNG.runSuitesSequentially(TestNG.java:1274)
at org.testng.TestNG.runSuitesLocally(TestNG.java:1208)
at org.testng.TestNG.runSuites(TestNG.java:1112)
at org.testng.TestNG.run(TestNG.java:1079)
at com.intellij.rt.testng.IDEARemoteTestNG.run(IDEARemoteTestNG.java:66)
at com.intellij.rt.testng.RemoteTestNGStarter.main(RemoteTestNGStarter.java:109)
]]>
            </full-stacktrace>
          </exception> <!-- java.lang.Throwable -->
          <reporter-output>
          </reporter-output>
        </test-method> <!-- test4 -->
      </class> <!-- DemoTestNG.DummyTests -->
    </test> <!-- TestNG -->
  </suite> <!-- Default Suite -->
</testng-results>
